Workbook

Sheet Raw Responses
A1: Timestamp | B1: What year are you currently in? | C1: What course/branch are you studying? | D1: How many different platforms/tools do you regularly use to keep track of college-related tasks and deadlines? | E1: What do you currently use to manage your deadlines/tasks? | F1: How often do you forget or miss an important college-related task/deadline? | G1: What types of things do you most commonly forget or struggle to keep track of? | H1: What is the biggest difficulty you face while managing these responsibilities? | I1: Tell us about a recent time when you forgot or nearly missed something important. What happened? | J1: What do you currently dislike about the tools/apps you use for managing your college work? | K1: If you could improve ONE thing about how you currently manage your college responsibilities, what would you change?
A2: 2026-09-10 00:03:33.977000 | B2: 4th | C2: BTECH CORE | D2: 0-1 | E2: Whatsapp, Google Calendar, College LMS/portal, Dairy/notebook | F2: Very Often | G2: Assignments, Exams, Form/application deadlines, Faculty meetings | H2: Deadline | I2: Shree ram sir Blocked me 😔 | J2: The credit limit | K2: I will change the placement cell
A3: 2026-09-10 00:08:06.497000 | B3: 4th | C3: CSE CORE | D3: 2-3 | E3: Dairy/notebook, Phone alarms/reminders | F3: Rarely | G3: Other | H3: Time management | I3: I missed an application form before deadline. | J3: Not accurate, or no knowledge of perfect tools. | K3: Time management
A4: 2026-09-10 00:09:42.686000 | B4: 4th | C4: B.Tech in Computer Science and Engineering (CSE) | D4: 2-3 | E4: Whatsapp, Google Calender, Google Calendar, College LMS/portal, To-do app, Excel/Google Sheets, Phone alarms/reminders | F4: Sometimes | G4: Assignments, Form/application deadlines, Project Deadlines, College events, Internship/placement applicationns, Interviews | H4: Keeping track of deadlines scattered across different platforms and remembering tasks that have different due dates and priorities. | I4: I recently almost missed a college application deadline because the information was shared in mail and got buried under other messages. I noticed it only when the deadline was approaching and had to complete the application quickly. | J4: The information is scattered across the college portal, email, and calendars. There is no single place that shows all my upcoming deadlines and priorities. | K4: I would create one centralized system that automatically collects deadlines from different platforms and gives reminders based on priority and urgency.
A5: 2026-09-10 00:12:25.424000 | B5: 3rd | C5: Btech aiml cse | D5: 2-3 | E5: Whatsapp, Google Calender | F5: Rarely | G5: Assignments | H5: To much work at once | I5: Yesterday | J5: They don't remind me consistently | K5: Some kind of alarm when deadline are near
A6: 2026-09-10 00:16:07.417000 | B6: 4th | C6: Btech Cse | D6: 0-1 | E6: Whatsapp | F6: Sometimes | G6: Assignments, Form/application deadlines | H6: Remembering all these | I6: I almost missed an assignment deadline because I forgot to note it down. A friend reminded me just in time, and I submitted it before the deadline | J6: Information is spread across multiple apps, making it easy to miss important updates and deadlines. | K6: I would like all assignments, exams, and deadlines to be organized in one place with reminders.
A7: 2026-09-10 00:17:12.832000 | B7: 4th | C7: Computer Science and Engineering | D7: 4-5 | E7: Whatsapp, Phone alarms/reminders | F7: Sometimes | G7: Assignments, Form/application deadlines, Internship/placement applicationns, Personal Tasks | H7: Keeping track of tasks and remembering to work on them at the right time. I sometimes remember a task too early or only after I was supposed to do it, even when I know it needs to be done. | I7: Recently, I missed the deadline for filling out a few placement forms. I remembered about them too late, and by then the applications had closed, so I was no longer eligible to sit for those companies. As a result, I lost a few placement opportunities. | J7: The tools I currently use are scattered and require too much manual effort. WhatsApp messages can get lost, Notes become messy as the number of tasks increases, and I have to create a new reminder every time I get a task—which I sometimes forget to do. With the large volume of emails we receive, important ones can also easily get buried. | K7: I would like to have one reliable system where all my responsibilities are tracked automatically, rather than having to remember them myself or manually create reminders. It should remind me early enough and again closer to the deadline so I have multiple chances to act on them.
A8: 2026-09-10 00:19:45.097000 | B8: 4th | C8: CSE | D8: 4-5 | E8: To-do app | F8: Sometimes | G8: Exams | H8: Forget important things. | I8: I become stressed | J8: UI is not good. | K8: Give the notification alarm for important thing.
A9: 2026-09-10 00:20:12.908000 | B9: 1st | C9: AI | D9: 2-3 | E9: Phone alarms/reminders | F9: Rarely | G9: Assignments | H9: Managing my time between classes, assignments and studies | I9: I recently almost missed an assignment deadline because I had multiple classes and tasks to manage at the same time. I completed it just before the deadline. | J9: Important information is spread across different apps, so it is sometimes difficult to keep track of everything in one place. | K9: I would improve my time management by keeping all my college tasks, deadlines, and reminders organized in one place.
A10: 2026-09-10 00:22:37.972000 | B10: 4th | C10: B.Tech | D10: 6+ | E10: Whatsapp, College LMS/portal | F10: Sometimes | G10: Assignments, Exams, Project Deadlines | H10: Managing my time between studies, assignments, and personal responsibilities. | I10: I almost missed an assignment deadline because I forgot about it while handling other work. | J10: I have to use different apps for different tasks, which can be confusing. | K10: I would like one simple app to manage all my college tasks and deadlines.
A11: 2026-09-10 00:22:53.402000 | B11: 4th | C11: Computer Science and Engineering | D11: 2-3 | E11: Whatsapp, College LMS/portal, Dairy/notebook, Phone alarms/reminders | F11: Often | G11: Assignments, Exams, Form/application deadlines, Project Deadlines, Faculty meetings, College events, Internship/placement applicationns | H11: Managing multiple things at once | I11: I misssed the online assignment streak of coding | J11: No reminders | K11: Manage thing systematically
A12: 2026-09-10 00:23:22.331000 | B12: 4th | C12: Cse Core | D12: 2-3 | E12: I don't use any specific system | F12: Rarely | G12: Internship/placement applicationns | J12: They do not update it from time to time | K12: I want to be better version of myself as compare to previous day.
A13: 2026-09-10 00:23:23.941000 | B13: 4th | C13: Btech. Computer Science and Engineering | D13: 0-1 | E13: I don't use any specific system | F13: Never | G13: Form/application deadlines
A14: 2026-09-10 00:24:14.147000 | B14: 4th | C14: B.Tech | D14: 2-3 | E14: To-do app, I don't use any specific system | F14: Sometimes | G14: Assignments, Form/application deadlines | H14: I forget the deadline at last moment. I remember till 11:00 but forget at 12:00 | I14: An assignment form given 1 week ago which I had already completed | J14: I still forget
A15: 2026-09-10 00:26:51.796000 | B15: 1st | C15: Integrated M.Tech Computational and Data Science | D15: 2-3 | E15: Whatsapp, Other | F15: Rarely | G15: Form/application deadlines, Faculty meetings, Personal Tasks | H15: Not the biggest difficulty but ...I am living alone and I have to cook for myself and all the homestuff also ...so i am facing a difficulty a little to manage aal college things | I15: Yeah I missed to submit assignment | J15: The due date in Google classroom | K15: I would change my sleep and other stuffs to manage college responsibilities
A16: 2026-09-10 00:27:05.517000 | B16: 4th | C16: Computer Science and Engineering | D16: 6+ | E16: Whatsapp, Google Calender, Notion, College LMS/portal, To-do app, Excel/Google Sheets, Dairy/notebook, Phone alarms/reminders, Other | F16: Rarely | G16: Personal Tasks | H16: Struggle with completing them within the given deadline | I16: Missed to attend ppt of a company that can for placement drive in my college | J16: Updating the applications to the latest version and also a lot of unnecessary notifications | K16: Be more careful and punctual
A17: 2026-09-10 00:32:25.634000 | B17: 4th | C17: Computer Science and Engineering | D17: 2-3 | E17: Whatsapp, Dairy/notebook, Phone alarms/reminders | F17: Sometimes | G17: Form/application deadlines, Project Deadlines | H17: The biggest difficulty is keeping track of different deadlines. Important dates are often shared on email or in different places, so sometimes I forget about a form, application or project deadline until it is very close. | I17: Recently, I almost missed a project deadline because the deadline was shared earlier on email and I did not keep track of it separately. I remembered it when the deadline was getting close and had to finish the remaining work quickly. | J17: I use WhatsApp, a diary/notebook and phone reminders, but none of them gives me a complete view of everything. I have to check different places to know what deadlines and tasks are coming up. | K17: I would want one place where I can keep track of all my forms, applications, project deadlines and other important college tasks, so I do not have to depend on WhatsApp messages, notes and separate reminders.
A18: 2026-09-10 00:32:43.999000 | B18: 1st | C18: Cs(ai and ml) | D18: 2-3 | E18: Whatsapp, Google Calender, Google Calendar, Excel/Google Sheets, Phone alarms/reminders | F18: Sometimes | G18: Assignments | H18: Nothing | I18: Missed a extra class at 2pm which is on my calendar | J18: They are alright but we are using them in a wrong way | K18: I will edit these applications and apply a alarm ringtone on these important events
A19: 2026-09-10 00:50:27.002000 | B19: 1st | C19: Bca | D19: 0-1 | E19: Google Calendar, Notion, To-do app, Dairy/notebook | F19: Sometimes | G19: Form/application deadlines, Project Deadlines, Faculty meetings | H19: I forgot | I19: I many time missed my assignment | J19: Thier ui | K19: Nothing but laziness
A20: 2026-09-10 00:51:30.345000 | B20: 4th | C20: Btech | D20: 0-1 | E20: Google Calender | F20: Sometimes | G20: Assignments, Form/application deadlines, Project Deadlines | H20: Remembering all things | I20: Latest form submission deadline | J20: No actual reminders | K20: Submit the task before deadline
A21: 2026-09-10 00:56:52.700000 | B21: 4th | C21: B.Tech Computer Science and Engineering | D21: 0-1 | E21: Notion | F21: Rarely | G21: Form/application deadlines | H21: The tracking application is not a sinhle one, but many, so hard to manage and track responsibility | I21: 1week prior, i forgot to apply for a internship | J21: One app only offer one out two features for taking not all essential tracking features | K21: All in one single tracking app
A22: 2026-09-10 01:18:58.846000 | B22: 2nd | C22: Cse core | D22: 2-3 | E22: Whatsapp, Google Calendar, College LMS/portal | F22: Rarely | G22: Assignments, Project Deadlines, Internship/placement applicationns | H22: Reminder problem | I22: Assignment was missed because I forgot the the deadline | J22: Writing assignments manually | K22: I would make myself more responsible towards how I manage my time
A23: 2026-09-10 01:26:23.213000 | B23: 4th | C23: Computer Science and Engineering | D23: 6+ | E23: Google Calender, Phone alarms/reminders | F23: Rarely | G23: Form/application deadlines, College events, Internship/placement applicationns, Personal Tasks | H23: The biggest difficulty is procrastination. Sometimes I tend to delay tasks, especially when I have multiple things to handle at the same time, due to which it feels unnecessary pressure as the deadline gets closer. | I23: I don't remember anything I missed anything important. I missed some unimportant things, which really didn't matter at the end. | J23: One thing is that I make unrealistic to-do lists and then, never follows them from the heart. So, it's not about the app, it's basically my problem. | K23: I would really want to improve my time management to avoid last-minute pressure.
A24: 2026-09-10 07:01:03.895000 | B24: 3rd | C24: Ba honours | D24: 4-5 | E24: Whatsapp, Google Calender, College LMS/portal, To-do app | F24: Rarely | G24: Form/application deadlines, Project Deadlines | H24: Balancing lectures, study time, assignments, and personal life without getting overwhelmed. | I24: Nothing | J24: I dislike having to switch between multiple platforms (like WhatsApp, email, and the college portal) | K24: Having a single, unified dashboard where all deadlines, timetables, and links are kept in one accessible place.
A25: 2026-09-10 12:07:52.777000 | B25: 2nd | C25: Bba | D25: 4-5 | E25: Whatsapp | F25: Very Often | G25: Assignments, Exams, Project Deadlines | H25: No | I25: No | J25: No | K25: No
A26: 2026-09-11 12:04:11.673000 | B26: 4th | C26: CSE | D26: 2-3 | E26: Whatsapp, Phone alarms/reminders | F26: Sometimes | G26: Assignments, Project Deadlines | H26: Sleep late | I26: Project deadline | J26: interface | K26: schedule

Sheet Quantitative Analysis
A1: Quantitative Analysis — What Do the Numbers Tell Us?
A2: Source: Raw Responses sheet. All counts and percentages below are calculated with formulas directly from the raw survey data (25 total responses). Nothing in this sheet is manually entered as a fixed number.
A4: A. Sample Overview
A5: Total respondents | C5: =COUNTA('Raw Responses'!$B$2:$B$26) -> 25
A7: Year of Study | B7: Count | C7: % of Respondents
A8: 1st | B8: =COUNTIF('Raw Responses'!$B$2:$B$26,A8) -> 4 | C8: =B8/COUNTA('Raw Responses'!$B$2:$B$26) -> 0.16
A9: 2nd | B9: =COUNTIF('Raw Responses'!$B$2:$B$26,A9) -> 2 | C9: =B9/COUNTA('Raw Responses'!$B$2:$B$26) -> 0.08
A10: 3rd | B10: =COUNTIF('Raw Responses'!$B$2:$B$26,A10) -> 2 | C10: =B10/COUNTA('Raw Responses'!$B$2:$B$26) -> 0.08
A11: 4th | B11: =COUNTIF('Raw Responses'!$B$2:$B$26,A11) -> 17 | C11: =B11/COUNTA('Raw Responses'!$B$2:$B$26) -> 0.68
A12: Total | B12: =SUM(B8:B11) -> 25 | C12: =SUM(C8:C11) -> 1
A14: B. Number of Tools/Platforms Used (self-reported)
A15: Number of Tools Used | B15: Count | C15: % of Respondents
A16: 0-1 | B16: =COUNTIF('Raw Responses'!$D$2:$D$26,A16) -> 6 | C16: =B16/COUNTA('Raw Responses'!$B$2:$B$26) -> 0.24
A17: 2-3 | B17: =COUNTIF('Raw Responses'!$D$2:$D$26,A17) -> 12 | C17: =B17/COUNTA('Raw Responses'!$B$2:$B$26) -> 0.48
A18: 4-5 | B18: =COUNTIF('Raw Responses'!$D$2:$D$26,A18) -> 4 | C18: =B18/COUNTA('Raw Responses'!$B$2:$B$26) -> 0.16
A19: 6+ | B19: =COUNTIF('Raw Responses'!$D$2:$D$26,A19) -> 3 | C19: =B19/COUNTA('Raw Responses'!$B$2:$B$26) -> 0.12
A20: Total | B20: =SUM(B16:B19) -> 25 | C20: =SUM(C16:C19) -> 1
A21: % using 2 or more tools | C21: =1-(B16/COUNTA('Raw Responses'!$B$2:$B$26)) -> 0.76
A22: "2 or more tools" = all respondents NOT in the "0-1" bin, based on the survey's own categorical question.
A24: C. Frequency of Forgetting/Missing Important Tasks
A25: Frequency | B25: Count | C25: % of Respondents
A26: Never | B26: =COUNTIF('Raw Responses'!$F$2:$F$26,A26) -> 1 | C26: =B26/COUNTA('Raw Responses'!$B$2:$B$26) -> 0.04
A27: Rarely | B27: =COUNTIF('Raw Responses'!$F$2:$F$26,A27) -> 10 | C27: =B27/COUNTA('Raw Responses'!$B$2:$B$26) -> 0.4
A28: Sometimes | B28: =COUNTIF('Raw Responses'!$F$2:$F$26,A28) -> 11 | C28: =B28/COUNTA('Raw Responses'!$B$2:$B$26) -> 0.44
A29: Often | B29: =COUNTIF('Raw Responses'!$F$2:$F$26,A29) -> 1 | C29: =B29/COUNTA('Raw Responses'!$B$2:$B$26) -> 0.04
A30: Very Often | B30: =COUNTIF('Raw Responses'!$F$2:$F$26,A30) -> 2 | C30: =B30/COUNTA('Raw Responses'!$B$2:$B$26) -> 0.08
A31: Total | B31: =SUM(B26:B30) -> 25 | C31: =SUM(C26:C30) -> 1
A32: % reporting Sometimes / Often / Very Often | C32: =(COUNTIF('Raw Responses'!$F$2:$F$26,"Sometimes")+COUNTIF('Raw Responses'!$F$2:$F$26,"Often")+COUNTIF('Raw Responses'!$F$2:$F$26,"Very Often"))/COUNTA('Raw Responses'!$B$2:$B$26) -> 0.56
A34: D. Types of Things Students Forget or Struggle to Track (multi-select)
A35: This was a multi-select question, so one respondent can appear in more than one row. Figures below are 'mentions', not unique respondents.
A36: Category | B36: Mentions | C36: % of Respondents Mentioning
A37: Assignments | B37: =SUMPRODUCT(--ISNUMBER(SEARCH(A37,'Raw Responses'!$G$2:$G$26))) -> 14 | C37: =B37/COUNTA('Raw Responses'!$B$2:$B$26) -> 0.56
A38: Exams | B38: =SUMPRODUCT(--ISNUMBER(SEARCH(A38,'Raw Responses'!$G$2:$G$26))) -> 5 | C38: =B38/COUNTA('Raw Responses'!$B$2:$B$26) -> 0.2
A39: Form/application deadlines | B39: =SUMPRODUCT(--ISNUMBER(SEARCH(A39,'Raw Responses'!$G$2:$G$26))) -> 14 | C39: =B39/COUNTA('Raw Responses'!$B$2:$B$26) -> 0.56
A40: Project Deadlines | B40: =SUMPRODUCT(--ISNUMBER(SEARCH(A40,'Raw Responses'!$G$2:$G$26))) -> 10 | C40: =B40/COUNTA('Raw Responses'!$B$2:$B$26) -> 0.4
A41: Faculty meetings | B41: =SUMPRODUCT(--ISNUMBER(SEARCH(A41,'Raw Responses'!$G$2:$G$26))) -> 4 | C41: =B41/COUNTA('Raw Responses'!$B$2:$B$26) -> 0.16
A42: College events | B42: =SUMPRODUCT(--ISNUMBER(SEARCH(A42,'Raw Responses'!$G$2:$G$26))) -> 3 | C42: =B42/COUNTA('Raw Responses'!$B$2:$B$26) -> 0.12
A43: Internship/placement applicationns | B43: =SUMPRODUCT(--ISNUMBER(SEARCH(A43,'Raw Responses'!$G$2:$G$26))) -> 6 | C43: =B43/COUNTA('Raw Responses'!$B$2:$B$26) -> 0.24
A44: Personal Tasks | B44: =SUMPRODUCT(--ISNUMBER(SEARCH(A44,'Raw Responses'!$G$2:$G$26))) -> 4 | C44: =B44/COUNTA('Raw Responses'!$B$2:$B$26) -> 0.16
A45: Interviews | B45: =SUMPRODUCT(--ISNUMBER(SEARCH(A45,'Raw Responses'!$G$2:$G$26))) -> 1 | C45: =B45/COUNTA('Raw Responses'!$B$2:$B$26) -> 0.04
...

Sheet Charts
A1: Research Dashboard — College Student Productivity Survey (n = 25)

Sheet Qualitative Analysis
A1: Qualitative Analysis — Response-by-Response Read
A2: Biggest Difficulty, Recent Incident, Dislike, and Improve columns are pulled directly (by formula) from the Raw Responses sheet — nothing is reworded. "Theme(s) Detected" is the researcher's manual thematic coding of that respondent's answers, based only on what they actually wrote. A blank cell means the respondent left that question empty in the original form.
A4: Response # | B4: Year | C4: Biggest Difficulty | D4: Recent Incident | E4: What They Dislike About Current Tools | F4: What They Would Improve | G4: Theme(s) Detected
A5: 1 | B5: ='Raw Responses'!B2 -> 4th | C5: =IF('Raw Responses'!H2="","(no response)",'Raw Responses'!H2) -> Deadline | D5: =IF('Raw Responses'!I2="","(no response)",'Raw Responses'!I2) -> Shree ram sir Blocked me 😔 | E5: =IF('Raw Responses'!J2="","(no response)",'Raw Responses'!J2) -> The credit limit | F5: =IF('Raw Responses'!K2="","(no response)",'Raw Responses'!K2) -> I will change the placement cell | G5: Other/Unclear
A6: 2 | B6: ='Raw Responses'!B3 -> 4th | C6: =IF('Raw Responses'!H3="","(no response)",'Raw Responses'!H3) -> Time management | D6: =IF('Raw Responses'!I3="","(no response)",'Raw Responses'!I3) -> I missed an application form before deadline. | E6: =IF('Raw Responses'!J3="","(no response)",'Raw Responses'!J3) -> Not accurate, or no knowledge of perfect tools. | F6: =IF('Raw Responses'!K3="","(no response)",'Raw Responses'!K3) -> Time management | G6: Time management; Other/Unclear
A7: 3 | B7: ='Raw Responses'!B4 -> 4th | C7: =IF('Raw Responses'!H4="","(no response)",'Raw Responses'!H4) -> Keeping track of deadlines scattered across different platforms and remembering tasks that have different due dates and priorities. | D7: =IF('Raw Responses'!I4="","(no response)",'Raw Responses'!I4) -> I recently almost missed a college application deadline because the information was shared in mail and got buried under other messages. I noticed it only when the deadline was approaching and had to complete the application quickly. | E7: =IF('Raw Responses'!J4="","(no response)",'Raw Responses'!J4) -> The information is scattered across the college portal, email, and calendars. There is no single place that shows all my upcoming deadlines and priorities. | F7: =IF('Raw Responses'!K4="","(no response)",'Raw Responses'!K4) -> I would create one centralized system that automatically collects deadlines from different platforms and gives reminders based on priority and urgency. | G7: Information scattered across platforms; Prioritization
A8: 4 | B8: ='Raw Responses'!B5 -> 3rd | C8: =IF('Raw Responses'!H5="","(no response)",'Raw Responses'!H5) -> To much work at once | D8: =IF('Raw Responses'!I5="","(no response)",'Raw Responses'!I5) -> Yesterday | E8: =IF('Raw Responses'!J5="","(no response)",'Raw Responses'!J5) -> They don't remind me consistently | F8: =IF('Raw Responses'!K5="","(no response)",'Raw Responses'!K5) -> Some kind of alarm when deadline are near | G8: Overload; Reminder/notification problems
A9: 5 | B9: ='Raw Responses'!B6 -> 4th | C9: =IF('Raw Responses'!H6="","(no response)",'Raw Responses'!H6) -> Remembering all these | D9: =IF('Raw Responses'!I6="","(no response)",'Raw Responses'!I6) -> I almost missed an assignment deadline because I forgot to note it down. A friend reminded me just in time, and I submitted it before the deadline | E9: =IF('Raw Responses'!J6="","(no response)",'Raw Responses'!J6) -> Information is spread across multiple apps, making it easy to miss important updates and deadlines. | F9: =IF('Raw Responses'!K6="","(no response)",'Raw Responses'!K6) -> I would like all assignments, exams, and deadlines to be organized in one place with reminders. | G9: Information scattered across platforms; Manual tracking; Reminder/notification problems
A10: 6 | B10: ='Raw Responses'!B7 -> 4th | C10: =IF('Raw Responses'!H7="","(no response)",'Raw Responses'!H7) -> Keeping track of tasks and remembering to work on them at the right time. I sometimes remember a task too early or only after I was supposed to do it, even when I know it needs to be done. | D10: =IF('Raw Responses'!I7="","(no response)",'Raw Responses'!I7) -> Recently, I missed the deadline for filling out a few placement forms. I remembered about them too late, and by then the applications had closed, so I was no longer eligible to sit for those companies. As a result, I lost a few placement opportunities. | E10: =IF('Raw Responses'!J7="","(no response)",'Raw Responses'!J7) -> The tools I currently use are scattered and require too much manual effort. WhatsApp messages can get lost, Notes become messy as the number of tasks increases, and I have to create a new reminder every time I get a task—which I sometimes forget to do. With the large volume of emails we receive, important ones can also easily get buried. | F10: =IF('Raw Responses'!K7="","(no response)",'Raw Responses'!K7) -> I would like to have one reliable system where all my responsibilities are tracked automatically, rather than having to remember them myself or manually create reminders. It should remind me early enough and again closer to the deadline so I have multiple chances to act on them. | G10: Information scattered across platforms; Manual tracking; Manual reminder creation; Overload
A11: 7 | B11: ='Raw Responses'!B8 -> 4th | C11: =IF('Raw Responses'!H8="","(no response)",'Raw Responses'!H8) -> Forget important things. | D11: =IF('Raw Responses'!I8="","(no response)",'Raw Responses'!I8) -> I become stressed | E11: =IF('Raw Responses'!J8="","(no response)",'Raw Responses'!J8) -> UI is not good. | F11: =IF('Raw Responses'!K8="","(no response)",'Raw Responses'!K8) -> Give the notification alarm for important thing. | G11: Reminder/notification problems; Other/Unclear
A12: 8 | B12: ='Raw Responses'!B9 -> 1st | C12: =IF('Raw Responses'!H9="","(no response)",'Raw Responses'!H9) -> Managing my time between classes, assignments and studies | D12: =IF('Raw Responses'!I9="","(no response)",'Raw Responses'!I9) -> I recently almost missed an assignment deadline because I had multiple classes and tasks to manage at the same time. I completed it just before the deadline. | E12: =IF('Raw Responses'!J9="","(no response)",'Raw Responses'!J9) -> Important information is spread across different apps, so it is sometimes difficult to keep track of everything in one place. | F12: =IF('Raw Responses'!K9="","(no response)",'Raw Responses'!K9) -> I would improve my time management by keeping all my college tasks, deadlines, and reminders organized in one place. | G12: Time management; Competing responsibilities; Information scattered across platforms
A13: 9 | B13: ='Raw Responses'!B10 -> 4th | C13: =IF('Raw Responses'!H10="","(no response)",'Raw Responses'!H10) -> Managing my time between studies, assignments, and personal responsibilities. | D13: =IF('Raw Responses'!I10="","(no response)",'Raw Responses'!I10) -> I almost missed an assignment deadline because I forgot about it while handling other work. | E13: =IF('Raw Responses'!J10="","(no response)",'Raw Responses'!J10) -> I have to use different apps for different tasks, which can be confusing. | F13: =IF('Raw Responses'!K10="","(no response)",'Raw Responses'!K10) -> I would like one simple app to manage all my college tasks and deadlines. | G13: Time management; Competing responsibilities; Information scattered across platforms
A14: 10 | B14: ='Raw Responses'!B11 -> 4th | C14: =IF('Raw Responses'!H11="","(no response)",'Raw Responses'!H11) -> Managing multiple things at once | D14: =IF('Raw Responses'!I11="","(no response)",'Raw Responses'!I11) -> I misssed the online assignment streak of coding | E14: =IF('Raw Responses'!J11="","(no response)",'Raw Responses'!J11) -> No reminders | F14: =IF('Raw Responses'!K11="","(no response)",'Raw Responses'!K11) -> Manage thing systematically | G14: Overload; Reminder/notification problems
A15: 11 | B15: ='Raw Responses'!B12 -> 4th | C15: =IF('Raw Responses'!H12="","(no response)",'Raw Responses'!H12) -> (no response) | D15: =IF('Raw Responses'!I12="","(no response)",'Raw Responses'!I12) -> (no response) | E15: =IF('Raw Responses'!J12="","(no response)",'Raw Responses'!J12) -> They do not update it from time to time | F15: =IF('Raw Responses'!K12="","(no response)",'Raw Responses'!K12) -> I want to be better version of myself as compare to previous day. | G15: Other/Unclear
A16: 12 | B16: ='Raw Responses'!B13 -> 4th | C16: =IF('Raw Responses'!H13="","(no response)",'Raw Responses'!H13) -> (no response) | D16: =IF('Raw Responses'!I13="","(no response)",'Raw Responses'!I13) -> (no response) | E16: =IF('Raw Responses'!J13="","(no response)",'Raw Responses'!J13) -> (no response) | F16: =IF('Raw Responses'!K13="","(no response)",'Raw Responses'!K13) -> (no response) | G16: No major problem
... A29: 25 | B29: ='Raw Responses'!B26 -> 4th | C29: =IF('Raw Responses'!H26="","(no response)",'Raw Responses'!H26) -> Sleep late | D29: =IF('Raw Responses'!I26="","(no response)",'Raw Responses'!I26) -> Project deadline | E29: =IF('Raw Responses'!J26="","(no response)",'Raw Responses'!J26) -> interface | F29: =IF('Raw Responses'!K26="","(no response)",'Raw Responses'!K26) -> schedule | G29: Time management; Other/Unclear

Sheet Theme Summary
A1: Theme Summary — Qualitative Findings
A2: "Number of students mentioning it" is calculated with a formula that counts how many rows in the Qualitative Analysis sheet contain that theme text. A response can count toward more than one theme, so the column will not add up to 25.
A4: Theme | B4: Students Mentioning | C4: % of Respondents (n=25) | D4: Example Evidence (short excerpt) | E4: User Impact | F4: Confidence
A5: Reminder/notification problems | B5: =COUNTIF('Qualitative Analysis'!$G$5:$G$29,"*"&A5&"*") -> 8 | C5: =B5/25 -> 0.32 | D5: "no actual reminders" / "don't remind me consistently" | E5: Reminders are missing, inconsistent, or not trusted, so tasks slip through even when noted somewhere. | F5: Moderately-to-strongly supported (tied for most-mentioned theme)
A6: Information scattered across platforms | B6: =COUNTIF('Qualitative Analysis'!$G$5:$G$29,"*"&A6&"*") -> 8 | C6: =B6/25 -> 0.32 | D6: "scattered across the college portal, email, and calendars" | E6: Important information lives in many places, so students must actively check multiple apps to stay on top of deadlines. | F6: Moderately-to-strongly supported
A7: Manual tracking | B7: =COUNTIF('Qualitative Analysis'!$G$5:$G$29,"*"&A7&"*") -> 8 | C7: =B7/25 -> 0.32 | D7: "I forgot to note it down" / "I still forget" | E7: Students rely on manually remembering or writing tasks down rather than an automated system, which is easy to fail under load. | F7: Moderately-to-strongly supported
A8: Time management | B8: =COUNTIF('Qualitative Analysis'!$G$5:$G$29,"*"&A8&"*") -> 7 | C8: =B8/25 -> 0.28 | D8: "managing my time between classes, assignments and studies" | E8: Students struggle to allocate time across academic tasks, which contributes to last-minute work and missed items. | F8: Moderately supported
A9: Competing responsibilities | B9: =COUNTIF('Qualitative Analysis'!$G$5:$G$29,"*"&A9&"*") -> 5 | C9: =B9/25 -> 0.2 | D9: "living alone and I have to cook for myself" | E9: Non-academic responsibilities (personal life, chores, part-time commitments) compete with college tasks for attention. | F9: Moderately supported
A10: Overload | B10: =COUNTIF('Qualitative Analysis'!$G$5:$G$29,"*"&A10&"*") -> 3 | C10: =B10/25 -> 0.12 | D10: "too much work at once" | E10: Having many tasks simultaneously makes it harder to keep track of any single one. | F10: Weakly-to-moderately supported
A11: Procrastination | B11: =COUNTIF('Qualitative Analysis'!$G$5:$G$29,"*"&A11&"*") -> 2 | C11: =B11/25 -> 0.08 | D11: "make unrealistic to-do lists and then never follow them" | E11: Some students self-identify delay/avoidance, not tooling, as the root cause of missed tasks. | F11: Weakly supported (small n)
A12: Manual reminder creation | B12: =COUNTIF('Qualitative Analysis'!$G$5:$G$29,"*"&A12&"*") -> 1 | C12: =B12/25 -> 0.04 | D12: "have to create a new reminder every time I get a task" | E12: Some students must manually set up every reminder themselves, with no automatic capture of deadlines. | F12: Weakly supported (single respondent)
A13: Prioritization | B13: =COUNTIF('Qualitative Analysis'!$G$5:$G$29,"*"&A13&"*") -> 1 | C13: =B13/25 -> 0.04 | D13: "tasks that have different due dates and priorities" | E13: Difficulty judging which task matters most when several are due close together. | F13: Weakly supported (single respondent)
A14: No major problem | B14: =COUNTIF('Qualitative Analysis'!$G$5:$G$29,"*"&A14&"*") -> 2 | C14: =B14/25 -> 0.08 | D14: Reported "Never" missing deadlines / answered "No" to all follow-up questions | E14: A minority of respondents report no meaningful problem — worth segmenting out rather than designing for. | F14: Weakly supported (small n)
A15: Other/Unclear | B15: =COUNTIF('Qualitative Analysis'!$G$5:$G$29,"*"&A15&"*") -> 11 | C15: =B15/25 -> 0.44 | D15: Responses that were blank, off-topic, or too ambiguous to categorize | E15: Not a validated finding — flagged so it is not mistaken for a real theme. | F15: N/A — catch-all, not a theme

Sheet Pain Point Summary
A1: Pain Point Summary — From Research Themes to PM Pain Points
A2: Each pain point below is built from one or more themes in the Theme Summary sheet. "Frequency/Research Signal" pulls its count directly from that sheet. Root Cause and Product Opportunity are the researcher's interpretation, not directly measured — they are hypotheses to validate, not conclusions.
A4: Pain Point | B4: Evidence | C4: Frequency/Research Signal | D4: User Impact | E4: Possible Root Cause | F4: Product Opportunity | G4: Confidence | H4: Validation Needed?
A5: Deadline-relevant information is scattered across too many channels | B5: Students describe checking WhatsApp, email, the college portal, and calendars separately to know what is due. | C5: ='Theme Summary'!B6&" of 25 students ("&TEXT('Theme Summary'!C6,"0%")&")" -> 8 of 25 students (32%) | D5: Students must actively hunt for deadline information instead of having it surfaced to them, raising the chance something is missed. | E5: No single source of truth exists for college-related tasks; each channel (LMS, email, WhatsApp groups) owns only part of the picture. | F5: There may be an opportunity to aggregate or surface deadlines from multiple sources in one place. This is a hypothesis about direction, not a specific feature. | G5: Moderate-to-strong | H5: Yes — confirm which specific channels matter most and whether students would trust an aggregator with that data.
A6: Task tracking is manual and easy to abandon under load | B6: Respondents describe writing tasks down, trying to remember them, or forgetting to log them altogether. | C6: ='Theme Summary'!B7&" of 25 students ("&TEXT('Theme Summary'!C7,"0%")&")" -> 8 of 25 students (32%) | D6: When tracking depends on manual effort, it breaks down exactly when students are busiest — which is when missed deadlines are most costly. | E6: Existing tools (notebooks, to-do apps, WhatsApp) require the student to notice, enter, and maintain every task themselves. | F6: There may be an opportunity to reduce manual data entry, e.g. by capturing deadlines automatically from a source students already use. Needs validation before scoping. | G6: Moderate-to-strong | H6: Yes — validate which task types (assignments, forms, exams) are most worth automating first.
A7: Reminders are missing, inconsistent, or not trusted | B7: Students report tools that "don't remind me consistently" or having "no actual reminders" at all. | C7: ='Theme Summary'!B5&" of 25 students ("&TEXT('Theme Summary'!C5,"0%")&")" -> 8 of 25 students (32%) | D7: Even when a task is recorded somewhere, a weak reminder system means it can still be missed. | E7: Current tools either lack reminders, require the student to set each one manually, or send too many low-priority notifications that get ignored. | F7: There may be an opportunity in smarter, priority-based reminders rather than a flat notification stream. Direction only — not a defined feature. | G7: Moderate-to-strong | H7: Yes — test what "the right reminder" looks like (timing, channel, priority) with real users before building anything.
A8: Competing time demands make it hard to plan around deadlines | B8: Some students cite balancing personal responsibilities (e.g. living alone, chores) or multiple simultaneous academic tasks. | C8: ='Theme Summary'!B9&" of 25 students ("&TEXT('Theme Summary'!C9,"0%")&")" -> 5 of 25 students (20%) | D8: This is a time-management and life-context problem, not purely a tooling gap — a tool alone may not fully solve it. | E8: College tasks compete with non-academic responsibilities and other coursework for the same limited time and attention. | F8: Any solution should account for prioritization/workload visibility, not just reminders. Needs further segmentation research. | G8: Moderate | H8: Yes — this pain point may need a different type of solution (planning/prioritization) than the fragmentation and reminder pain points above.
A9: A minority of students report no meaningful problem | B9: 2 respondents said they "Never" miss deadlines or answered "No" to every follow-up question. | C9: ='Theme Summary'!B14&" of 25 students ("&TEXT('Theme Summary'!C14,"0%")&")" -> 2 of 25 students (8%) | D9: Not every student is a target user — some may already have workable systems or low task complexity. | E9: Likely fewer competing responsibilities, fewer tools/tasks to juggle, or simply lower survey engagement (short, low-effort answers). | F9: Not a product opportunity — useful mainly for excluding a segment from the target user definition. | G9: Weak (small n) | H9: Not a priority — but worth keeping in mind when defining who the product is NOT for.

Sheet Key Insights & PM Conclusion
A1: Key Insights & PM Conclusion
A3: A. Top 5 Key Insights
A4: Insight | B4: Evidence | C4: Why It Matters for the Product
A5: Missing deadlines is a common, not rare, experience in this sample. | B5: 56% of respondents (14/25) report forgetting/missing tasks Sometimes, Often, or Very Often. | C5: This is a frequent enough problem to be worth solving, rather than an edge case.
A6: Students already use several tools, but the tools don't add up to one system. | B6: 76% of respondents use 2+ tools (per the tool-count question), and WhatsApp — a messaging app, not a task manager — is the single most-mentioned tool (15 mentions). | C6: The gap isn't a total lack of tools; it's the lack of one that pulls everything together.
A7: Assignments and form/application deadlines are the most commonly forgotten items. | B7: 14 mentions each out of 62 total mentions across all 'things forgotten' categories. | C7: Any early solution should prioritize these two task types over less-mentioned ones (e.g. interviews, 1 mention).
A8: Weak reminders and manual tracking are mentioned as often as information scattering. | B8: All three themes sit at 8/25 (32%) in the Theme Summary — a three-way tie, not one dominant theme. | C8: The problem is not a single narrow issue; multiple related pain points would need to be addressed together.
A9: A small subset of students report no real problem at all. | B9: 2 respondents (8%) said they 'Never' miss deadlines or answered 'No' to every open-ended question. | C9: Not every student is an equally strong target user — this subset should likely be excluded from early targeting.
A11: B. Strongest User Problems (Ranked)
A12: Ranking considers frequency (how many students mentioned it) AND user impact (how disruptive it sounds in respondents' own words) together — frequency alone is not treated as the same thing as severity, per the Theme Summary and Pain Point Summary sheets.
A13: Rank | B13: Problem | C13: Why This Rank
A14: 1 | B14: Information scattered across platforms / channels | C14: Tied for most-mentioned (8/25) AND multiple respondents describe direct consequences (missed application deadlines, buried emails) — high frequency and clear impact.
A15: 2 | B15: Weak or inconsistent reminders | C15: Tied for most-mentioned (8/25); several respondents link this directly to a specific missed task, suggesting real impact, not just annoyance.
A16: 3 | B16: Manual, effort-heavy tracking | C16: Tied for most-mentioned (8/25); overlaps with the two problems above, since manual tracking is often the reason reminders/scattering matter.
A17: 4 | B17: Time management / competing responsibilities | C17: Mentioned by 7/25 and 5/25 respectively; real but appears to be a broader life-management issue that a tool may only partly address.
A18: 5 | B18: Procrastination | C18: Only 2/25 respondents self-identified this directly; too small a signal to prioritize yet, but worth tracking in further research.
A20: C. Research Limitations
A21: • Small sample size: only 25 responses, which limits how confidently findings generalize to the wider student population.
A22: • Uneven year distribution: 17 of 25 respondents (68%) are 4th-year students; 1st, 2nd, and 3rd year are each represented by only 2-4 respondents, so year-based comparisons are not reliable.
A23: • Uneven course/branch distribution: the sample is dominated by Computer Science-related branches (CSE, AI/ML, BTech CSE), with only a few non-CS respondents (e.g. BBA, BA Honours, BCA).
A24: • Self-reported data: frequency of forgetting and difficulty descriptions rely on respondents' own memory and self-assessment, which can be inconsistent (e.g. one respondent reported 'Very Often' missing deadlines but answered 'No' to every open-ended follow-up question).
A25: • Single data-collection method: all data comes from one Google Form; no interviews or observational data are available to cross-check these self-reports.
A26: • Some responses are incomplete or low-effort: several respondents left open-ended questions blank or gave very short, low-detail answers, which limits the depth of qualitative analysis available.
A28: D. Target User Hypothesis
A29: HYPOTHESIS (not directly proven by this data): Later-year engineering/CS students who juggle multiple parallel commitments — coursework, project deadlines, and internship/placement applications — appear most likely to benefit, since this group is over-represented among respondents reporting frequent missed deadlines and multi-channel information scattering. This is a hypothesis because the sample's year and branch skew make it impossible to confirm this group is more affected than others who are simply under-represented here.
A31: E. Draft Problem Statement
A32: College students, especially those managing several parallel deadlines (assignments, forms, project and placement deadlines), struggle to keep track of important tasks because the information lives across many separate channels (WhatsApp, email, college portal, calendars) and current reminder systems are weak or manually maintained, resulting in missed deadlines, lost opportunities (e.g. placement applications), and last-minute stress.
A34: F. Product Opportunity (direction only — no feature set yet)
... A41: • Only after validation, move on to defining a specific MVP and feature set — this workbook intentionally stops short of that step.
